2016-05-28 15:03:12,001 - __main__ - INFO - Start reading database
2016-05-28 15:03:12,001 - __main__ - DEBUG - Records: {'john': 55, 'tom': 66}
2016-05-28 15:03:12,001 - __main__ - INFO - Updating records ...
2016-05-28 15:03:12,001 - __main__ - INFO - Finish updating records
2016-05-28 15:03:12,002 - __main__ - ERROR - Failed to open file
Traceback (most recent call last):
  File "logger_ex.py", line 24, in <module>
    open('/path/to/does/not/exist', 'rb')
IOError: [Errno 2] No such file or directory: '/path/to/does/not/exist'
